Workbook

Sheet Raw Data
A1: Age | B1: Attrition | C1: BusinessTravel | D1: Department | E1: DistanceFromHome | F1: Education | G1: EducationField | H1: EmployeeID | I1: Gender | J1: JobLevel | K1: JobRole | L1: MaritalStatus | M1: MonthlyIncome | N1: NumCompaniesWorked | O1: PercentSalaryHike | P1: StockOptionLevel | Q1: TotalWorkingYears | R1: TrainingTimesLastYear | S1: YearsAtCompany | T1: YearsSinceLastPromotion | U1: YearsWithCurrManager | V1: EnvironmentSatisfaction | W1: JobSatisfaction | X1: WorkLifeBalance | Y1: JobInvolvement | Z1: PerformanceRating
A2: 51 | B2: No | C2: Travel_Rarely | D2: Sales | E2: 6 | F2: 2 | G2: Life Sciences | H2: 1 | I2: Female | J2: 1 | K2: Healthcare Representative | L2: Married | M2: 131160 | N2: 1 | O2: 11 | P2: 0 | Q2: 1 | R2: 6 | S2: 1 | T2: 0 | U2: 0 | V2: 3 | W2: 4 | X2: 2 | Y2: 3 | Z2: 3
A3: 31 | B3: Yes | C3: Travel_Frequently | D3: Research & Development | E3: 10 | F3: 1 | G3: Life Sciences | H3: 2 | I3: Female | J3: 1 | K3: Research Scientist | L3: Single | M3: 41890 | N3: 0 | O3: 23 | P3: 1 | Q3: 6 | R3: 3 | S3: 5 | T3: 1 | U3: 4 | V3: 3 | W3: 2 | X3: 4 | Y3: 2 | Z3: 4
A4: 32 | B4: No | C4: Travel_Frequently | D4: Research & Development | E4: 17 | F4: 4 | G4: Other | H4: 3 | I4: Male | J4: 4 | K4: Sales Executive | L4: Married | M4: 193280 | N4: 1 | O4: 15 | P4: 3 | Q4: 5 | R4: 2 | S4: 5 | T4: 0 | U4: 3 | V4: 2 | W4: 2 | X4: 1 | Y4: 3 | Z4: 3
A5: 38 | B5: No | C5: Non-Travel | D5: Research & Development | E5: 2 | F5: 5 | G5: Life Sciences | H5: 4 | I5: Male | J5: 3 | K5: Human Resources | L5: Married | M5: 83210 | N5: 3 | O5: 11 | P5: 3 | Q5: 13 | R5: 5 | S5: 8 | T5: 7 | U5: 5 | V5: 4 | W5: 4 | X5: 3 | Y5: 2 | Z5: 3
A6: 32 | B6: No | C6: Travel_Rarely | D6: Research & Development | E6: 10 | F6: 1 | G6: Medical | H6: 5 | I6: Male | J6: 1 | K6: Sales Executive | L6: Single | M6: 23420 | N6: 4 | O6: 12 | P6: 2 | Q6: 9 | R6: 2 | S6: 6 | T6: 0 | U6: 4 | V6: 4 | W6: 1 | X6: 3 | Y6: 3 | Z6: 3
A7: 46 | B7: No | C7: Travel_Rarely | D7: Research & Development | E7: 8 | F7: 3 | G7: Life Sciences | H7: 6 | I7: Female | J7: 4 | K7: Research Director | L7: Married | M7: 40710 | N7: 3 | O7: 13 | P7: 0 | Q7: 28 | R7: 5 | S7: 7 | T7: 7 | U7: 7 | V7: 3 | W7: 2 | X7: 2 | Y7: 3 | Z7: 3
A8: 28 | B8: Yes | C8: Travel_Rarely | D8: Research & Development | E8: 11 | F8: 2 | G8: Medical | H8: 7 | I8: Male | J8: 2 | K8: Sales Executive | L8: Single | M8: 58130 | N8: 2 | O8: 20 | P8: 1 | Q8: 5 | R8: 2 | S8: 0 | T8: 0 | U8: 0 | V8: 1 | W8: 3 | X8: 1 | Y8: 3 | Z8: 4
A9: 29 | B9: No | C9: Travel_Rarely | D9: Research & Development | E9: 18 | F9: 3 | G9: Life Sciences | H9: 8 | I9: Male | J9: 2 | K9: Sales Executive | L9: Married | M9: 31430 | N9: 2 | O9: 22 | P9: 3 | Q9: 10 | R9: 2 | S9: 0 | T9: 0 | U9: 0 | V9: 1 | W9: 2 | X9: 3 | Y9: 3 | Z9: 4
A10: 31 | B10: No | C10: Travel_Rarely | D10: Research & Development | E10: 1 | F10: 3 | G10: Life Sciences | H10: 9 | I10: Male | J10: 3 | K10: Laboratory Technician | L10: Married | M10: 20440 | N10: 0 | O10: 21 | P10: 0 | Q10: 10 | R10: 2 | S10: 9 | T10: 7 | U10: 8 | V10: 2 | W10: 4 | X10: 3 | Y10: 3 | Z10: 4
A11: 25 | B11: No | C11: Non-Travel | D11: Research & Development | E11: 7 | F11: 4 | G11: Medical | H11: 10 | I11: Female | J11: 4 | K11: Laboratory Technician | L11: Divorced | M11: 134640 | N11: 1 | O11: 13 | P11: 1 | Q11: 6 | R11: 2 | S11: 6 | T11: 1 | U11: 5 | V11: 2 | W11: 1 | X11: 3 | Y11: 3 | Z11: 3
A12: 45 | B12: No | C12: Travel_Rarely | D12: Research & Development | E12: 17 | F12: 2 | G12: Medical | H12: 11 | I12: Male | J12: 2 | K12: Laboratory Technician | L12: Married | M12: 79910 | N12: 0 | O12: 13 | P12: 2 | Q12: 21 | R12: 2 | S12: 20 | T12: 4 | U12: 10 | V12: 3 | W12: 4 | X12: 3 | Y12: 2 | Z12: 3
A13: 36 | B13: No | C13: Travel_Rarely | D13: Research & Development | E13: 28 | F13: 1 | G13: Life Sciences | H13: 12 | I13: Male | J13: 1 | K13: Laboratory Technician | L13: Married | M13: 33770 | N13: 0 | O13: 12 | P13: 2 | Q13: 16 | R13: 2 | S13: 15 | T13: 10 | U13: 11 | W13: 4 | X13: 3 | Y13: 3 | Z13: 3
A14: 55 | B14: No | C14: Travel_Rarely | D14: Research & Development | E14: 14 | F14: 4 | G14: Life Sciences | H14: 13 | I14: Female | J14: 1 | K14: Sales Executive | L14: Single | M14: 55380 | N14: 0 | O14: 17 | P14: 0 | Q14: 37 | R14: 2 | S14: 36 | T14: 4 | U14: 13 | V14: 4 | W14: 1 | X14: 3 | Y14: 3 | Z14: 3
A15: 47 | B15: Yes | C15: Non-Travel | D15: Research & Development | E15: 1 | F15: 1 | G15: Medical | H15: 14 | I15: Male | J15: 1 | K15: Research Scientist | L15: Married | M15: 57620 | N15: 1 | O15: 11 | P15: 2 | Q15: 10 | R15: 4 | S15: 10 | T15: 9 | U15: 9 | V15: 1 | W15: 2 | X15: 2 | Y15: 2 | Z15: 3
A16: 28 | B16: No | C16: Travel_Rarely | D16: Research & Development | E16: 1 | F16: 3 | G16: Life Sciences | H16: 15 | I16: Male | J16: 1 | K16: Manufacturing Director | L16: Married | M16: 25920 | N16: 1 | O16: 14 | P16: 0 | Q16: 5 | R16: 2 | S16: 5 | T16: 0 | U16: 4 | V16: 4 | W16: 4 | X16: 2 | Y16: 3 | Z16: 3
A17: 37 | B17: No | C17: Travel_Rarely | D17: Research & Development | E17: 1 | F17: 3 | G17: Life Sciences | H17: 16 | I17: Male | J17: 2 | K17: Healthcare Representative | L17: Married | M17: 53460 | N17: 4 | O17: 11 | P17: 0 | Q17: 7 | R17: 2 | S17: 5 | T17: 0 | U17: 1 | V17: 3 | W17: 4 | X17: 4 | Y17: 3 | Z17: 3
A18: 21 | B18: No | C18: Travel_Rarely | D18: Research & Development | E18: 3 | F18: 2 | G18: Life Sciences | H18: 17 | I18: Male | J18: 1 | K18: Laboratory Technician | L18: Single | M18: 42130 | N18: 1 | O18: 12 | P18: 3 | Q18: 3 | R18: 3 | S18: 3 | T18: 1 | U18: 0 | V18: 4 | W18: 3 | X18: 4 | Y18: 2 | Z18: 3
A19: 37 | B19: No | C19: Non-Travel | D19: Research & Development | E19: 1 | F19: 3 | G19: Medical | H19: 18 | I19: Male | J19: 2 | K19: Sales Executive | L19: Divorced | M19: 41270 | N19: 2 | O19: 13 | P19: 1 | Q19: 15 | R19: 2 | S19: 5 | T19: 0 | U19: 2 | V19: 1 | W19: 4 | X19: 3 | Y19: 3 | Z19: 3
A20: 35 | B20: No | C20: Travel_Rarely | D20: Sales | E20: 7 | F20: 4 | G20: Life Sciences | H20: 19 | I20: Male | J20: 1 | K20: Sales Representative | L20: Divorced | M20: 24380 | N20: 7 | O20: 16 | P20: 0 | Q20: 10 | R20: 5 | S20: 7 | T20: 6 | U20: 2 | V20: 2 | W20: 2 | X20: 2 | Y20: 2 | Z20: 3
A21: 38 | B21: No | C21: Travel_Rarely | D21: Research & Development | E21: 8 | F21: 3 | G21: Life Sciences | H21: 20 | I21: Female | J21: 1 | K21: Manager | L21: Divorced | M21: 68700 | N21: 1 | O21: 11 | P21: 1 | Q21: 8 | R21: 5 | S21: 8 | T21: 7 | U21: 7 | V21: 1 | W21: 1 | X21: 3 | Y21: 3 | Z21: 3
A22: 26 | B22: No | C22: Travel_Frequently | D22: Research & Development | E22: 1 | F22: 4 | G22: Other | H22: 21 | I22: Male | J22: 2 | K22: Laboratory Technician | L22: Divorced | M22: 104470 | N22: 1 | O22: 18 | P22: 0 | Q22: 6 | R22: 3 | S22: 6 | T22: 1 | U22: 4 | V22: 3 | W22: 2 | X22: 1 | Y22: 3 | Z22: 3
A23: 50 | B23: No | C23: Travel_Rarely | D23: Sales | E23: 8 | F23: 4 | G23: Life Sciences | H23: 22 | I23: Male | J23: 1 | K23: Research Scientist | L23: Divorced | M23: 96670 | N23: 3 | O23: 23 | P23: 0 | Q23: 28 | R23: 2 | S23: 10 | T23: 1 | U23: 6 | V23: 1 | W23: 2 | X23: 2 | Y23: 2 | Z23: 4
A24: 53 | B24: No | C24: Travel_Rarely | D24: Research & Development | E24: 11 | F24: 4 | G24: Life Sciences | H24: 23 | I24: Female | J24: 2 | K24: Research Scientist | L24: Married | M24: 21480 | N24: 3 | O24: 11 | P24: 0 | Q24: 21 | R24: 2 | S24: 5 | T24: 1 | U24: 3 | V24: 3 | W24: 3 | X24: 2 | Y24: 3 | Z24: 3
A25: 42 | B25: No | C25: Travel_Rarely | D25: Research & Development | E25: 4 | F25: 4 | G25: Life Sciences | H25: 24 | I25: Male | J25: 1 | K25: Manufacturing Director | L25: Married | M25: 89260 | N25: 1 | O25: 14 | P25: 0 | R25: 4 | S25: 20 | T25: 11 | U25: 6 | V25: 2 | W25: 3 | X25: 3 | Y25: 1 | Z25: 3
A26: 29 | B26: No | C26: Travel_Frequently | D26: Research & Development | E26: 16 | F26: 4 | G26: Medical | H26: 25 | I26: Male | J26: 1 | K26: Laboratory Technician | L26: Single | M26: 65130 | N26: 1 | O26: 11 | P26: 1 | Q26: 10 | R26: 2 | S26: 10 | T26: 0 | U26: 9 | V26: 2 | W26: 4 | X26: 2 | Y26: 3 | Z26: 3
A27: 55 | B27: No | C27: Travel_Rarely | D27: Research & Development | E27: 1 | F27: 4 | G27: Other | H27: 26 | I27: Female | J27: 1 | K27: Research Scientist | L27: Married | M27: 67990 | N27: 3 | O27: 11 | P27: 0 | Q27: 12 | R27: 2 | S27: 10 | T27: 0 | U27: 8 | V27: 2 | W27: 4 | X27: 3 | Y27: 3 | Z27: 3
A28: 26 | B28: No | C28: Travel_Frequently | D28: Research & Development | E28: 9 | F28: 3 | G28: Life Sciences | H28: 27 | I28: Female | J28: 1 | K28: Manager | L28: Married | M28: 162910 | N28: 1 | O28: 22 | P28: 0 | Q28: 5 | R28: 3 | S28: 5 | T28: 3 | U28: 3 | V28: 1 | W28: 1 | X28: 3 | Y28: 3 | Z28: 4
A29: 37 | B29: No | C29: Travel_Rarely | D29: Sales | E29: 5 | F29: 1 | G29: Marketing | H29: 28 | I29: Male | J29: 1 | K29: Research Scientist | L29: Single | M29: 27050 | N29: 1 | O29: 11 | P29: 0 | Q29: 17 | R29: 2 | S29: 17 | T29: 5 | U29: 7 | V29: 4 | W29: 4 | X29: 3 | Y29: 3 | Z29: 3
A30: 44 | B30: Yes | C30: Travel_Frequently | D30: Research & Development | E30: 1 | F30: 2 | G30: Medical | H30: 29 | I30: Male | J30: 2 | K30: Research Scientist | L30: Divorced | M30: 103330 | N30: 3 | O30: 14 | P30: 1 | Q30: 19 | R30: 2 | S30: 1 | T30: 0 | U30: 0 | V30: 4 | W30: 3 | X30: 1 | Y30: 2 | Z30: 3
A31: 38 | B31: No | C31: Travel_Rarely | D31: Sales | E31: 2 | F31: 3 | G31: Marketing | H31: 30 | I31: Female | J31: 1 | K31: Manager | L31: Divorced | M31: 44480 | N31: 9 | O31: 12 | P31: 0 | Q31: 10 | R31: 3 | S31: 2 | T31: 1 | U31: 2 | V31: 4 | W31: 4 | X31: 3 | Y31: 2 | Z31: 3
A32: 26 | B32: Yes | C32: Travel_Rarely | D32: Research & Development | E32: 4 | F32: 3 | G32: Medical | H32: 31 | I32: Male | J32: 3 | K32: Research Scientist | L32: Divorced | M32: 68540 | N32: 2 | O32: 11 | P32: 0 | Q32: 5 | R32: 5 | S32: 3 | T32: 0 | U32: 2 | V32: 1 | W32: 2 | X32: 3 | Y32: 2 | Z32: 3
A33: 28 | B33: No | C33: Travel_Rarely | D33: Research & Development | E33: 7 | F33: 3 | G33: Other | H33: 32 | I33: Male | J33: 1 | K33: Human Resources | L33: Single | M33: 96370 | N33: 1 | O33: 13 | P33: 0 | Q33: 5 | R33: 6 | S33: 5 | T33: 0 | U33: 2 | V33: 4 | W33: 4 | X33: 3 | Y33: 2 | Z33: 3
A34: 49 | B34: No | C34: Travel_Frequently | D34: Research & Development | E34: 1 | F34: 1 | G34: Medical | H34: 33 | I34: Female | J34: 2 | K34: Research Scientist | L34: Single | M34: 35910 | N34: 9 | O34: 13 | P34: 0 | Q34: 22 | R34: 2 | S34: 3 | T34: 1 | U34: 2 | V34: 3 | W34: 1 | X34: 3 | Y34: 3 | Z34: 3
A35: 36 | B35: No | C35: Travel_Rarely | D35: Sales | E35: 5 | F35: 3 | G35: Technical Degree | H35: 34 | I35: Male | J35: 3 | K35: Sales Executive | L35: Single | M35: 54050 | N35: 4 | O35: 14 | P35: 0 | Q35: 10 | R35: 2 | S35: 8 | T35: 7 | U35: 7 | V35: 3 | W35: 2 | X35: 3 | Y35: 3 | Z35: 3
A36: 31 | B36: No | C36: Travel_Frequently | D36: Research & Development | E36: 9 | F36: 4 | G36: Medical | H36: 35 | I36: Male | J36: 1 | K36: Sales Executive | L36: Divorced | M36: 46840 | N36: 1 | O36: 16 | P36: 1 | Q36: 2 | R36: 4 | S36: 2 | T36: 2 | U36: 2 | V36: 4 | W36: 2 | X36: 2 | Y36: 3 | Z36: 3
A37: 26 | B37: Yes | C37: Travel_Rarely | D37: Research & Development | E37: 8 | F37: 3 | G37: Medical | H37: 36 | I37: Male | J37: 2 | K37: Manager | L37: Single | M37: 157870 | N37: 1 | O37: 12 | P37: 2 | Q37: 8 | R37: 5 | S37: 8 | T37: 7 | U37: 4 | V37: 4 | W37: 4 | X37: 3 | Y37: 3 | Z37: 3
... A41: 35 | B41: No | C41: Travel_Rarely | D41: Sales | E41: 20 | F41: 2 | G41: Life Sciences | H41: 40 | I41: Male | J41: 1 | K41: Laboratory Technician | L41: Married | M41: 51540 | N41: 0 | O41: 19 | P41: 0 | Q41: 12 | R41: 2 | S41: 11 | T41: 6 | U41: 9 | V41: 3 | W41: 2 | X41: 2 | Y41: 2 | Z41: 3
A42: 36 | B42: No | C42: Travel_Frequently | D42: Research & Development | E42: 8 | F42: 3 | G42: Other | H42: 41 | I42: Female | J42: 3 | K42: Sales Executive | L42: Married | M42: 69620 | N42: 4 | O42: 12 | P42: 2 | Q42: 4 | R42: 2 | S42: 1 | T42: 0 | U42: 0 | V42: 3 | X42: 3 | Y42: 2 | Z42: 3
A43: 51 | B43: No | C43: Travel_Rarely | D43: Research & Development | E43: 2 | F43: 3 | G43: Life Sciences | H43: 42 | I43: Male | J43: 2 | K43: Laboratory Technician | L43: Divorced | M43: 56750 | N43: 5 | O43: 13 | P43: 0 | Q43: 13 | R43: 2 | S43: 4 | T43: 1 | U43: 2 | V43: 4 | W43: 2 | X43: 3 | Y43: 2 | Z43: 3
...

Sheet Validation
A1: Data Validation
A3: Check | B3: Result
A4: Total employees | B4: =COUNTA('Raw Data'!H2:H4411) -> 4410
A5: Duplicate EmployeeID | B5: =SUMPRODUCT((COUNTIF('Raw Data'!H2:H4411,'Raw Data'!H2:H4411)>1)*1) -> 0
A6: Missing Age | B6: =COUNTBLANK('Raw Data'!A2:A4411) -> 0
A7: Missing MonthlyIncome | B7: =COUNTBLANK('Raw Data'!M2:M4411) -> 0
A8: Missing JobSatisfaction | B8: =COUNTBLANK('Raw Data'!W2:W4411) -> 20
A9: Missing EnvironmentSatisfaction | B9: =COUNTBLANK('Raw Data'!V2:V4411) -> 25
A11: Min Age | B11: =MIN('Raw Data'!A2:A4411) -> 18
A12: Max Age | B12: =MAX('Raw Data'!A2:A4411) -> 60
A13: Attrition Yes count | B13: =COUNTIF('Raw Data'!B2:B4411,"Yes") -> 711
A14: Attrition rate % | B14: =ROUND(COUNTIF('Raw Data'!B2:B4411,"Yes")/COUNTA('Raw Data'!H2:H4411)*100,1) -> 16.1

Sheet Risk Score
A1: EmployeeID | B1: Age | C1: Department | D1: JobRole | E1: TotalWorkingYears | F1: YearsWithCurrManager | G1: JobSatisfaction | H1: EnvironmentSatisfaction | I1: Risk_Score | J1: Risk_Tier
A2: ='Raw Data'!H2 -> 1 | B2: ='Raw Data'!A2 -> 51 | C2: ='Raw Data'!D2 -> Sales | D2: ='Raw Data'!K2 -> Healthcare Representative | E2: ='Raw Data'!Q2 -> 1 | F2: ='Raw Data'!U2 -> 0 | G2: ='Raw Data'!W2 -> 4 | H2: ='Raw Data'!V2 -> 3 | I2: =IF(AND(ISNUMBER(B2),B2<=25),2,0)+IF(AND(ISNUMBER(E2),E2<=5),2,0)+IF(AND(ISNUMBER(F2),F2<=1),2,0)+IF(AND(ISNUMBER(G2),G2<=2),1,0)+IF(AND(ISNUMBER(H2),H2<=2),1,0) -> 4 | J2: =IF(I2>=6,"High",IF(I2>=3,"Medium","Low")) -> Medium
A3: ='Raw Data'!H3 -> 2 | B3: ='Raw Data'!A3 -> 31 | C3: ='Raw Data'!D3 -> Research & Development | D3: ='Raw Data'!K3 -> Research Scientist | E3: ='Raw Data'!Q3 -> 6 | F3: ='Raw Data'!U3 -> 4 | G3: ='Raw Data'!W3 -> 2 | H3: ='Raw Data'!V3 -> 3 | I3: =IF(AND(ISNUMBER(B3),B3<=25),2,0)+IF(AND(ISNUMBER(E3),E3<=5),2,0)+IF(AND(ISNUMBER(F3),F3<=1),2,0)+IF(AND(ISNUMBER(G3),G3<=2),1,0)+IF(AND(ISNUMBER(H3),H3<=2),1,0) -> 1 | J3: =IF(I3>=6,"High",IF(I3>=3,"Medium","Low")) -> Low
A4: ='Raw Data'!H4 -> 3 | B4: ='Raw Data'!A4 -> 32 | C4: ='Raw Data'!D4 -> Research & Development | D4: ='Raw Data'!K4 -> Sales Executive | E4: ='Raw Data'!Q4 -> 5 | F4: ='Raw Data'!U4 -> 3 | G4: ='Raw Data'!W4 -> 2 | H4: ='Raw Data'!V4 -> 2 | I4: =IF(AND(ISNUMBER(B4),B4<=25),2,0)+IF(AND(ISNUMBER(E4),E4<=5),2,0)+IF(AND(ISNUMBER(F4),F4<=1),2,0)+IF(AND(ISNUMBER(G4),G4<=2),1,0)+IF(AND(ISNUMBER(H4),H4<=2),1,0) -> 4 | J4: =IF(I4>=6,"High",IF(I4>=3,"Medium","Low")) -> Medium
A5: ='Raw Data'!H5 -> 4 | B5: ='Raw Data'!A5 -> 38 | C5: ='Raw Data'!D5 -> Research & Development | D5: ='Raw Data'!K5 -> Human Resources | E5: ='Raw Data'!Q5 -> 13 | F5: ='Raw Data'!U5 -> 5 | G5: ='Raw Data'!W5 -> 4 | H5: ='Raw Data'!V5 -> 4 | I5: =IF(AND(ISNUMBER(B5),B5<=25),2,0)+IF(AND(ISNUMBER(E5),E5<=5),2,0)+IF(AND(ISNUMBER(F5),F5<=1),2,0)+IF(AND(ISNUMBER(G5),G5<=2),1,0)+IF(AND(ISNUMBER(H5),H5<=2),1,0) -> 0 | J5: =IF(I5>=6,"High",IF(I5>=3,"Medium","Low")) -> Low
A6: ='Raw Data'!H6 -> 5 | B6: ='Raw Data'!A6 -> 32 | C6: ='Raw Data'!D6 -> Research & Development | D6: ='Raw Data'!K6 -> Sales Executive | E6: ='Raw Data'!Q6 -> 9 | F6: ='Raw Data'!U6 -> 4 | G6: ='Raw Data'!W6 -> 1 | H6: ='Raw Data'!V6 -> 4 | I6: =IF(AND(ISNUMBER(B6),B6<=25),2,0)+IF(AND(ISNUMBER(E6),E6<=5),2,0)+IF(AND(ISNUMBER(F6),F6<=1),2,0)+IF(AND(ISNUMBER(G6),G6<=2),1,0)+IF(AND(ISNUMBER(H6),H6<=2),1,0) -> 1 | J6: =IF(I6>=6,"High",IF(I6>=3,"Medium","Low")) -> Low
A7: ='Raw Data'!H7 -> 6 | B7: ='Raw Data'!A7 -> 46 | C7: ='Raw Data'!D7 -> Research & Development | D7: ='Raw Data'!K7 -> Research Director | E7: ='Raw Data'!Q7 -> 28 | F7: ='Raw Data'!U7 -> 7 | G7: ='Raw Data'!W7 -> 2 | H7: ='Raw Data'!V7 -> 3 | I7: =IF(AND(ISNUMBER(B7),B7<=25),2,0)+IF(AND(ISNUMBER(E7),E7<=5),2,0)+IF(AND(ISNUMBER(F7),F7<=1),2,0)+IF(AND(ISNUMBER(G7),G7<=2),1,0)+IF(AND(ISNUMBER(H7),H7<=2),1,0) -> 1 | J7: =IF(I7>=6,"High",IF(I7>=3,"Medium","Low")) -> Low
A8: ='Raw Data'!H8 -> 7 | B8: ='Raw Data'!A8 -> 28 | C8: ='Raw Data'!D8 -> Research & Development | D8: ='Raw Data'!K8 -> Sales Executive | E8: ='Raw Data'!Q8 -> 5 | F8: ='Raw Data'!U8 -> 0 | G8: ='Raw Data'!W8 -> 3 | H8: ='Raw Data'!V8 -> 1 | I8: =IF(AND(ISNUMBER(B8),B8<=25),2,0)+IF(AND(ISNUMBER(E8),E8<=5),2,0)+IF(AND(ISNUMBER(F8),F8<=1),2,0)+IF(AND(ISNUMBER(G8),G8<=2),1,0)+IF(AND(ISNUMBER(H8),H8<=2),1,0) -> 5 | J8: =IF(I8>=6,"High",IF(I8>=3,"Medium","Low")) -> Medium
A9: ='Raw Data'!H9 -> 8 | B9: ='Raw Data'!A9 -> 29 | C9: ='Raw Data'!D9 -> Research & Development | D9: ='Raw Data'!K9 -> Sales Executive | E9: ='Raw Data'!Q9 -> 10 | F9: ='Raw Data'!U9 -> 0 | G9: ='Raw Data'!W9 -> 2 | H9: ='Raw Data'!V9 -> 1 | I9: =IF(AND(ISNUMBER(B9),B9<=25),2,0)+IF(AND(ISNUMBER(E9),E9<=5),2,0)+IF(AND(ISNUMBER(F9),F9<=1),2,0)+IF(AND(ISNUMBER(G9),G9<=2),1,0)+IF(AND(ISNUMBER(H9),H9<=2),1,0) -> 4 | J9: =IF(I9>=6,"High",IF(I9>=3,"Medium","Low")) -> Medium
A10: ='Raw Data'!H10 -> 9 | B10: ='Raw Data'!A10 -> 31 | C10: ='Raw Data'!D10 -> Research & Development | D10: ='Raw Data'!K10 -> Laboratory Technician | E10: ='Raw Data'!Q10 -> 10 | F10: ='Raw Data'!U10 -> 8 | G10: ='Raw Data'!W10 -> 4 | H10: ='Raw Data'!V10 -> 2 | I10: =IF(AND(ISNUMBER(B10),B10<=25),2,0)+IF(AND(ISNUMBER(E10),E10<=5),2,0)+IF(AND(ISNUMBER(F10),F10<=1),2,0)+IF(AND(ISNUMBER(G10),G10<=2),1,0)+IF(AND(ISNUMBER(H10),H10<=2),1,0) -> 1 | J10: =IF(I10>=6,"High",IF(I10>=3,"Medium","Low")) -> Low
A11: ='Raw Data'!H11 -> 10 | B11: ='Raw Data'!A11 -> 25 | C11: ='Raw Data'!D11 -> Research & Development | D11: ='Raw Data'!K11 -> Laboratory Technician | E11: ='Raw Data'!Q11 -> 6 | F11: ='Raw Data'!U11 -> 5 | G11: ='Raw Data'!W11 -> 1 | H11: ='Raw Data'!V11 -> 2 | I11: =IF(AND(ISNUMBER(B11),B11<=25),2,0)+IF(AND(ISNUMBER(E11),E11<=5),2,0)+IF(AND(ISNUMBER(F11),F11<=1),2,0)+IF(AND(ISNUMBER(G11),G11<=2),1,0)+IF(AND(ISNUMBER(H11),H11<=2),1,0) -> 4 | J11: =IF(I11>=6,"High",IF(I11>=3,"Medium","Low")) -> Medium
A12: ='Raw Data'!H12 -> 11 | B12: ='Raw Data'!A12 -> 45 | C12: ='Raw Data'!D12 -> Research & Development | D12: ='Raw Data'!K12 -> Laboratory Technician | E12: ='Raw Data'!Q12 -> 21 | F12: ='Raw Data'!U12 -> 10 | G12: ='Raw Data'!W12 -> 4 | H12: ='Raw Data'!V12 -> 3 | I12: =IF(AND(ISNUMBER(B12),B12<=25),2,0)+IF(AND(ISNUMBER(E12),E12<=5),2,0)+IF(AND(ISNUMBER(F12),F12<=1),2,0)+IF(AND(ISNUMBER(G12),G12<=2),1,0)+IF(AND(ISNUMBER(H12),H12<=2),1,0) -> 0 | J12: =IF(I12>=6,"High",IF(I12>=3,"Medium","Low")) -> Low
A13: ='Raw Data'!H13 -> 12 | B13: ='Raw Data'!A13 -> 36 | C13: ='Raw Data'!D13 -> Research & Development | D13: ='Raw Data'!K13 -> Laboratory Technician | E13: ='Raw Data'!Q13 -> 16 | F13: ='Raw Data'!U13 -> 11 | G13: ='Raw Data'!W13 -> 4 | H13: ='Raw Data'!V13 -> 0 | I13: =IF(AND(ISNUMBER(B13),B13<=25),2,0)+IF(AND(ISNUMBER(E13),E13<=5),2,0)+IF(AND(ISNUMBER(F13),F13<=1),2,0)+IF(AND(ISNUMBER(G13),G13<=2),1,0)+IF(AND(ISNUMBER(H13),H13<=2),1,0) -> 0 | J13: =IF(I13>=6,"High",IF(I13>=3,"Medium","Low")) -> Low
... A4411: ='Raw Data'!H4411 -> 4410 | B4411: ='Raw Data'!A4411 -> 40 | C4411: ='Raw Data'!D4411 -> Research & Development | D4411: ='Raw Data'!K4411 -> Laboratory Technician | E4411: ='Raw Data'!Q4411 -> 0 | F4411: ='Raw Data'!U4411 -> 9 | G4411: ='Raw Data'!W4411 -> 3 | H4411: ='Raw Data'!V4411 -> 1 | I4411: =IF(AND(ISNUMBER(B4411),B4411<=25),2,0)+IF(AND(ISNUMBER(E4411),E4411<=5),2,0)+IF(AND(ISNUMBER(F4411),F4411<=1),2,0)+IF(AND(ISNUMBER(G4411),G4411<=2),1,0)+IF(AND(ISNUMBER(H4411),H4411<=2),1,0) -> 1 | J4411: =IF(I4411>=6,"High",IF(I4411>=3,"Medium","Low")) -> Low

Sheet High Risk List
A1: High Risk Employees, sorted by Risk Score
A3: EmployeeID | B3: Age | C3: Department | D3: JobRole | E3: TotalWorkingYears | F3: YearsWithCurrManager | G3: JobSatisfaction | H3: EnvironmentSatisfaction | I3: Risk_Score
A4: ='Risk Score'!A201 -> 200 | B4: ='Risk Score'!B201 -> 18 | C4: ='Risk Score'!C201 -> Research & Development | D4: ='Risk Score'!D201 -> Sales Executive | E4: ='Risk Score'!E201 -> 0 | F4: ='Risk Score'!F201 -> 0 | G4: ='Risk Score'!G201 -> 2 | H4: ='Risk Score'!H201 -> 2 | I4: ='Risk Score'!I201 -> 8
A5: ='Risk Score'!A433 -> 432 | B5: ='Risk Score'!B433 -> 20 | C5: ='Risk Score'!C433 -> Research & Development | D5: ='Risk Score'!D433 -> Laboratory Technician | E5: ='Risk Score'!E433 -> 1 | F5: ='Risk Score'!F433 -> 0 | G5: ='Risk Score'!G433 -> 1 | H5: ='Risk Score'!H433 -> 1 | I5: ='Risk Score'!I433 -> 8
A6: ='Risk Score'!A478 -> 477 | B6: ='Risk Score'!B478 -> 22 | C6: ='Risk Score'!C478 -> Research & Development | D6: ='Risk Score'!D478 -> Sales Representative | E6: ='Risk Score'!E478 -> 4 | F6: ='Risk Score'!F478 -> 1 | G6: ='Risk Score'!G478 -> 1 | H6: ='Risk Score'!H478 -> 2 | I6: ='Risk Score'!I478 -> 8
A7: ='Risk Score'!A804 -> 803 | B7: ='Risk Score'!B804 -> 24 | C7: ='Risk Score'!C804 -> Sales | D7: ='Risk Score'!D804 -> Research Scientist | E7: ='Risk Score'!E804 -> 4 | F7: ='Risk Score'!F804 -> 0 | G7: ='Risk Score'!G804 -> 1 | H7: ='Risk Score'!H804 -> 2 | I7: ='Risk Score'!I804 -> 8
A8: ='Risk Score'!A1015 -> 1014 | B8: ='Risk Score'!B1015 -> 21 | C8: ='Risk Score'!C1015 -> Sales | D8: ='Risk Score'!D1015 -> Healthcare Representative | E8: ='Risk Score'!E1015 -> 1 | F8: ='Risk Score'!F1015 -> 0 | G8: ='Risk Score'!G1015 -> 2 | H8: ='Risk Score'!H1015 -> 2 | I8: ='Risk Score'!I1015 -> 8
A9: ='Risk Score'!A1363 -> 1362 | B9: ='Risk Score'!B1363 -> 19 | C9: ='Risk Score'!C1363 -> Research & Development | D9: ='Risk Score'!D1363 -> Manufacturing Director | E9: ='Risk Score'!E1363 -> 1 | F9: ='Risk Score'!F1363 -> 0 | G9: ='Risk Score'!G1363 -> 2 | H9: ='Risk Score'!H1363 -> 2 | I9: ='Risk Score'!I1363 -> 8
A10: ='Risk Score'!A1671 -> 1670 | B10: ='Risk Score'!B1671 -> 18 | C10: ='Risk Score'!C1671 -> Research & Development | D10: ='Risk Score'!D1671 -> Sales Executive | E10: ='Risk Score'!E1671 -> 0 | F10: ='Risk Score'!F1671 -> 0 | G10: ='Risk Score'!G1671 -> 2 | H10: ='Risk Score'!H1671 -> 2 | I10: ='Risk Score'!I1671 -> 8
A11: ='Risk Score'!A636 -> 635 | B11: ='Risk Score'!B636 -> 19 | C11: ='Risk Score'!C636 -> Sales | D11: ='Risk Score'!D636 -> Healthcare Representative | E11: ='Risk Score'!E636 -> 1 | F11: ='Risk Score'!F636 -> 0 | G11: ='Risk Score'!G636 -> 2 | H11: ='Risk Score'!H636 -> 1 | I11: ='Risk Score'!I636 -> 8
A12: ='Risk Score'!A2274 -> 2273 | B12: ='Risk Score'!B2274 -> 24 | C12: ='Risk Score'!C2274 -> Sales | D12: ='Risk Score'!D2274 -> Research Scientist | E12: ='Risk Score'!E2274 -> 4 | F12: ='Risk Score'!F2274 -> 0 | G12: ='Risk Score'!G2274 -> 1 | H12: ='Risk Score'!H2274 -> 2 | I12: ='Risk Score'!I2274 -> 8
A13: ='Risk Score'!A1903 -> 1902 | B13: ='Risk Score'!B1903 -> 20 | C13: ='Risk Score'!C1903 -> Research & Development | D13: ='Risk Score'!D1903 -> Laboratory Technician | E13: ='Risk Score'!E1903 -> 1 | F13: ='Risk Score'!F1903 -> 0 | G13: ='Risk Score'!G1903 -> 1 | H13: ='Risk Score'!H1903 -> 1 | I13: ='Risk Score'!I1903 -> 8
A14: ='Risk Score'!A1948 -> 1947 | B14: ='Risk Score'!B1948 -> 22 | C14: ='Risk Score'!C1948 -> Research & Development | D14: ='Risk Score'!D1948 -> Sales Representative | E14: ='Risk Score'!E1948 -> 4 | F14: ='Risk Score'!F1948 -> 1 | G14: ='Risk Score'!G1948 -> 1 | H14: ='Risk Score'!H1948 -> 2 | I14: ='Risk Score'!I1948 -> 8
A15: ='Risk Score'!A3418 -> 3417 | B15: ='Risk Score'!B3418 -> 22 | C15: ='Risk Score'!C3418 -> Research & Development | D15: ='Risk Score'!D3418 -> Sales Representative | E15: ='Risk Score'!E3418 -> 4 | F15: ='Risk Score'!F3418 -> 1 | G15: ='Risk Score'!G3418 -> 1 | H15: ='Risk Score'!H3418 -> 2 | I15: ='Risk Score'!I3418 -> 8
A16: ='Risk Score'!A2485 -> 2484 | B16: ='Risk Score'!B2485 -> 21 | C16: ='Risk Score'!C2485 -> Sales | D16: ='Risk Score'!D2485 -> Healthcare Representative | E16: ='Risk Score'!E2485 -> 1 | F16: ='Risk Score'!F2485 -> 0 | G16: ='Risk Score'!G2485 -> 2 | H16: ='Risk Score'!H2485 -> 2 | I16: ='Risk Score'!I2485 -> 8
A17: ='Risk Score'!A3141 -> 3140 | B17: ='Risk Score'!B3141 -> 18 | C17: ='Risk Score'!C3141 -> Research & Development | D17: ='Risk Score'!D3141 -> Sales Executive | E17: ='Risk Score'!E3141 -> 0 | F17: ='Risk Score'!F3141 -> 0 | G17: ='Risk Score'!G3141 -> 2 | H17: ='Risk Score'!H3141 -> 2 | I17: ='Risk Score'!I3141 -> 8
A18: ='Risk Score'!A3576 -> 3575 | B18: ='Risk Score'!B3576 -> 19 | C18: ='Risk Score'!C3576 -> Sales | D18: ='Risk Score'!D3576 -> Healthcare Representative | E18: ='Risk Score'!E3576 -> 1 | F18: ='Risk Score'!F3576 -> 0 | G18: ='Risk Score'!G3576 -> 2 | H18: ='Risk Score'!H3576 -> 1 | I18: ='Risk Score'!I3576 -> 8
A19: ='Risk Score'!A3955 -> 3954 | B19: ='Risk Score'!B3955 -> 21 | C19: ='Risk Score'!C3955 -> Sales | D19: ='Risk Score'!D3955 -> Healthcare Representative | E19: ='Risk Score'!E3955 -> 1 | F19: ='Risk Score'!F3955 -> 0 | G19: ='Risk Score'!G3955 -> 2 | H19: ='Risk Score'!H3955 -> 2 | I19: ='Risk Score'!I3955 -> 8
A20: ='Risk Score'!A4303 -> 4302 | B20: ='Risk Score'!B4303 -> 19 | C20: ='Risk Score'!C4303 -> Research & Development | D20: ='Risk Score'!D4303 -> Manufacturing Director | E20: ='Risk Score'!E4303 -> 1 | F20: ='Risk Score'!F4303 -> 0 | G20: ='Risk Score'!G4303 -> 2 | H20: ='Risk Score'!H4303 -> 2 | I20: ='Risk Score'!I4303 -> 8
A21: ='Risk Score'!A3373 -> 3372 | B21: ='Risk Score'!B3373 -> 20 | C21: ='Risk Score'!C3373 -> Research & Development | D21: ='Risk Score'!D3373 -> Laboratory Technician | E21: ='Risk Score'!E3373 -> 1 | F21: ='Risk Score'!F3373 -> 0 | G21: ='Risk Score'!G3373 -> 1 | H21: ='Risk Score'!H3373 -> 1 | I21: ='Risk Score'!I3373 -> 8
A22: ='Risk Score'!A3744 -> 3743 | B22: ='Risk Score'!B3744 -> 24 | C22: ='Risk Score'!C3744 -> Sales | D22: ='Risk Score'!D3744 -> Research Scientist | E22: ='Risk Score'!E3744 -> 4 | F22: ='Risk Score'!F3744 -> 0 | G22: ='Risk Score'!G3744 -> 1 | H22: ='Risk Score'!H3744 -> 2 | I22: ='Risk Score'!I3744 -> 8
A23: ='Risk Score'!A2106 -> 2105 | B23: ='Risk Score'!B2106 -> 19 | C23: ='Risk Score'!C2106 -> Sales | D23: ='Risk Score'!D2106 -> Healthcare Representative | E23: ='Risk Score'!E2106 -> 1 | F23: ='Risk Score'!F2106 -> 0 | G23: ='Risk Score'!G2106 -> 2 | H23: ='Risk Score'!H2106 -> 1 | I23: ='Risk Score'!I2106 -> 8
A24: ='Risk Score'!A2833 -> 2832 | B24: ='Risk Score'!B2833 -> 19 | C24: ='Risk Score'!C2833 -> Research & Development | D24: ='Risk Score'!D2833 -> Manufacturing Director | E24: ='Risk Score'!E2833 -> 1 | F24: ='Risk Score'!F2833 -> 0 | G24: ='Risk Score'!G2833 -> 2 | H24: ='Risk Score'!H2833 -> 2 | I24: ='Risk Score'!I2833 -> 8
A25: ='Risk Score'!A805 -> 804 | B25: ='Risk Score'!B805 -> 24 | C25: ='Risk Score'!C805 -> Research & Development | D25: ='Risk Score'!D805 -> Manager | E25: ='Risk Score'!E805 -> 1 | F25: ='Risk Score'!F805 -> 0 | G25: ='Risk Score'!G805 -> 2 | H25: ='Risk Score'!H805 -> 4 | I25: ='Risk Score'!I805 -> 7
A26: ='Risk Score'!A475 -> 474 | B26: ='Risk Score'!B475 -> 20 | C26: ='Risk Score'!C475 -> Research & Development | D26: ='Risk Score'!D475 -> Research Scientist | E26: ='Risk Score'!E475 -> 1 | F26: ='Risk Score'!F475 -> 0 | G26: ='Risk Score'!G475 -> 1 | H26: ='Risk Score'!H475 -> 4 | I26: ='Risk Score'!I475 -> 7
A27: ='Risk Score'!A471 -> 470 | B27: ='Risk Score'!B471 -> 18 | C27: ='Risk Score'!C471 -> Sales | D27: ='Risk Score'!D471 -> Manager | E27: ='Risk Score'!E471 -> 0 | F27: ='Risk Score'!F471 -> 0 | G27: ='Risk Score'!G471 -> 4 | H27: ='Risk Score'!H471 -> 2 | I27: ='Risk Score'!I471 -> 7
A28: ='Risk Score'!A269 -> 268 | B28: ='Risk Score'!B269 -> 24 | C28: ='Risk Score'!C269 -> Research & Development | D28: ='Risk Score'!D269 -> Healthcare Representative | E28: ='Risk Score'!E269 -> 4 | F28: ='Risk Score'!F269 -> 0 | G28: ='Risk Score'!G269 -> 3 | H28: ='Risk Score'!H269 -> 1 | I28: ='Risk Score'!I269 -> 7
A29: ='Risk Score'!A166 -> 165 | B29: ='Risk Score'!B166 -> 19 | C29: ='Risk Score'!C166 -> Research & Development | D29: ='Risk Score'!D166 -> Sales Executive | E29: ='Risk Score'!E166 -> 1 | F29: ='Risk Score'!F166 -> 0 | G29: ='Risk Score'!G166 -> 4 | H29: ='Risk Score'!H166 -> 1 | I29: ='Risk Score'!I166 -> 7
A30: ='Risk Score'!A114 -> 113 | B30: ='Risk Score'!B114 -> 21 | C30: ='Risk Score'!C114 -> Human Resources | D30: ='Risk Score'!D114 -> Laboratory Technician | E30: ='Risk Score'!E114 -> 1 | F30: ='Risk Score'!F114 -> 0 | G30: ='Risk Score'!G114 -> 2 | H30: ='Risk Score'!H114 -> 3 | I30: ='Risk Score'!I114 -> 7
A31: ='Risk Score'!A1055 -> 1054 | B31: ='Risk Score'!B1055 -> 18 | C31: ='Risk Score'!C1055 -> Research & Development | D31: ='Risk Score'!D1055 -> Sales Representative | E31: ='Risk Score'!E1055 -> 0 | F31: ='Risk Score'!F1055 -> 0 | G31: ='Risk Score'!G1055 -> 3 | H31: ='Risk Score'!H1055 -> 2 | I31: ='Risk Score'!I1055 -> 7
A32: ='Risk Score'!A1323 -> 1322 | B32: ='Risk Score'!B1323 -> 22 | C32: ='Risk Score'!C1323 -> Research & Development | D32: ='Risk Score'!D1323 -> Sales Representative | E32: ='Risk Score'!E1323 -> 1 | F32: ='Risk Score'!F1323 -> 0 | G32: ='Risk Score'!G1323 -> 4 | H32: ='Risk Score'!H1323 -> 2 | I32: ='Risk Score'!I1323 -> 7
A33: ='Risk Score'!A1636 -> 1635 | B33: ='Risk Score'!B1636 -> 19 | C33: ='Risk Score'!C1636 -> Research & Development | D33: ='Risk Score'!D1636 -> Sales Executive | E33: ='Risk Score'!E1636 -> 1 | F33: ='Risk Score'!F1636 -> 0 | G33: ='Risk Score'!G1636 -> 4 | H33: ='Risk Score'!H1636 -> 1 | I33: ='Risk Score'!I1636 -> 7
A34: ='Risk Score'!A1584 -> 1583 | B34: ='Risk Score'!B1584 -> 21 | C34: ='Risk Score'!C1584 -> Human Resources | D34: ='Risk Score'!D1584 -> Laboratory Technician | E34: ='Risk Score'!E1584 -> 1 | F34: ='Risk Score'!F1584 -> 0 | G34: ='Risk Score'!G1584 -> 2 | H34: ='Risk Score'!H1584 -> 3 | I34: ='Risk Score'!I1584 -> 7
A35: ='Risk Score'!A1739 -> 1738 | B35: ='Risk Score'!B1739 -> 24 | C35: ='Risk Score'!C1739 -> Research & Development | D35: ='Risk Score'!D1739 -> Healthcare Representative | E35: ='Risk Score'!E1739 -> 4 | F35: ='Risk Score'!F1739 -> 0 | G35: ='Risk Score'!G1739 -> 3 | H35: ='Risk Score'!H1739 -> 1 | I35: ='Risk Score'!I1739 -> 7
A36: ='Risk Score'!A1799 -> 1798 | B36: ='Risk Score'!B1799 -> 23 | C36: ='Risk Score'!C1799 -> Sales | D36: ='Risk Score'!D1799 -> Manufacturing Director | E36: ='Risk Score'!E1799 -> 1 | F36: ='Risk Score'!F1799 -> 0 | G36: ='Risk Score'!G1799 -> 1 | H36: ='Risk Score'!H1799 -> 3 | I36: ='Risk Score'!I1799 -> 7
A37: ='Risk Score'!A1701 -> 1700 | B37: ='Risk Score'!B1701 -> 20 | C37: ='Risk Score'!C1701 -> Research & Development | D37: ='Risk Score'!D1701 -> Sales Representative | E37: ='Risk Score'!E1701 -> 1 | F37: ='Risk Score'!F1701 -> 0 | G37: ='Risk Score'!G1701 -> 2 | H37: ='Risk Score'!H1701 -> 4 | I37: ='Risk Score'!I1701 -> 7
A38: ='Risk Score'!A1690 -> 1689 | B38: ='Risk Score'!B1690 -> 24 | C38: ='Risk Score'!C1690 -> Sales | D38: ='Risk Score'!D1690 -> Laboratory Technician | E38: ='Risk Score'!E1690 -> 1 | F38: ='Risk Score'!F1690 -> 0 | G38: ='Risk Score'!G1690 -> 2 | H38: ='Risk Score'!H1690 -> 4 | I38: ='Risk Score'!I1690 -> 7
A39: ='Risk Score'!A1182 -> 1181 | B39: ='Risk Score'!B1182 -> 23 | C39: ='Risk Score'!C1182 -> Research & Development | D39: ='Risk Score'!D1182 -> Manufacturing Director | E39: ='Risk Score'!E1182 -> 1 | F39: ='Risk Score'!F1182 -> 0 | G39: ='Risk Score'!G1182 -> 1 | H39: ='Risk Score'!H1182 -> 4 | I39: ='Risk Score'!I1182 -> 7
A40: ='Risk Score'!A1300 -> 1299 | B40: ='Risk Score'!B1300 -> 23 | C40: ='Risk Score'!C1300 -> Research & Development | D40: ='Risk Score'!D1300 -> Laboratory Technician | E40: ='Risk Score'!E1300 -> 3 | F40: ='Risk Score'!F1300 -> 0 | G40: ='Risk Score'!G1300 -> 1 | H40: ='Risk Score'!H1300 -> 3 | I40: ='Risk Score'!I1300 -> 7
A41: ='Risk Score'!A1391 -> 1390 | B41: ='Risk Score'!B1391 -> 19 | C41: ='Risk Score'!C1391 -> Research & Development | D41: ='Risk Score'!D1391 -> Sales Executive | E41: ='Risk Score'!E1391 -> 1 | F41: ='Risk Score'!F1391 -> 0 | G41: ='Risk Score'!G1391 -> 4 | H41: ='Risk Score'!H1391 -> 2 | I41: ='Risk Score'!I1391 -> 7
...
